Workbook
Name Cap_Pct: Inputs!$D$28
Name Cap_Threshold: Inputs!$D$29
Name Case: Inputs!$D$6
Name Cash_Yield: Inputs!$D$27
Name DCF_Exit_Multiple: DCF!$D$7
Name Diluted_Shares: Inputs!$D$11
Name EBITDA_Haircut: Inputs!$D$32
Name Equity_Risk_Premium: WACC!$D$18
Name Exit_Cost_Pct: Inputs!$D$20
Name Exit_Multiple: Inputs!$D$45
Name Fee_Amort_Years: Inputs!$D$14
Name Fin_Fee_Pct: Inputs!$D$13
Name Growth_Shift: Inputs!$D$30
Name Holding_Years: Inputs!$D$19
Name Hurdle_IRR: Inputs!$D$22
Name Kd_Pre_Tax: WACC!$D$21
Name Leverage_Scale: Inputs!$D$17
Name MIP_Pct: Inputs!$D$21
Name Margin_Shift: Inputs!$D$31
Name Mid_Year: DCF!$D$8
Name Min_Cash: Inputs!$D$15
Name Min_DSCR: Inputs!$D$39
Name Min_ICR: Inputs!$D$38
Name Offer_Premium: Inputs!$D$10
Name Rev_Commitment: Inputs!$D$35
Name Rev_Rate: Inputs!$D$36
Name Rev_Undrawn_Fee: Inputs!$D$37
Name Risk_Free: WACC!$D$17
Name Rollover_Pct: Inputs!$D$16
Name Size_Premium: WACC!$D$19
Name Sweep_Pct: Inputs!$D$18
Name Target_DC: WACC!$D$14
Name Target_MOIC: Inputs!$D$23
Name Tax_Rate: Inputs!$D$26
Name Terminal_Growth: DCF!$D$6
Name Txn_Fee_Pct: Inputs!$D$12
Name Unaffected_Price: Inputs!$D$9
Name WACC_Rate: WACC!$D$23

Sheet Cover
B2: Project Saffron
B3: Saffron Consumer Brands Ltd | LBO, DCF and valuation model | INR crore, fiscal years ending March
B4: ILLUSTRATIVE CASE: fictional company and invented figures, built to show the method.
B6: Headline outputs (live: follow the case selector on Inputs)
B7: Live case | D7: =CHOOSE(Case,"Base","Upside","Downside") -> Base
B8: Offer price per share | D8: =Deal!$D$6 -> 475
B9: Premium to unaffected price | D9: =Offer_Premium -> 0.25
B10: Entry EV / LTM EBITDA | D10: =Deal!$D$12 -> 13.823529
B11: Total debt / LTM EBITDA | D11: =Deal!$D$18 -> 4
B12: Sponsor equity | D12: =Deal!$D$36 -> 3655.24
B13: Sponsor IRR | D13: =Returns!$D$20 -> 0.20222862
B14: Sponsor MOIC | D14: =Returns!$D$16 -> 2.5115123
B15: DCF value per share (Gordon growth) | D15: =DCF!$D$31 -> 431.21642
B16: WACC | D16: =WACC_Rate -> 0.13093135
B17: Model integrity checks | D17: =Checks!$D$15 -> ALL CHECKS PASS
B19: How to read this workbook
B20: Blue cells on yellow are inputs. Black cells are formulas. Green cells link to another sheet.
B21: Every formula traces back to Inputs. Change the case selector (1 Base, 2 Upside, 3 Downside) or the shifts on Inputs and the whole model updates.
B22: Interest accrues on opening balances, so the model has no circular reference.
B23: Sensitivity and Football hold values computed by the STOCKEX engine; they do not update live.
B24: Sheets: Inputs, IS, BS, CF, Debt, Deal (sources and uses), Returns (exit, bridge, covenants), WACC, DCF, Comps, Sensitivity, Football, Checks.
B25: The STOCKEX test suite recomputes every formula in this file from the inputs and requires it to match the Python engine.

Sheet Inputs
B2: Inputs
B3: Every blue cell drives the model. Scenario blocks feed the live rows via the selector.
B5: Case selector
B6: Live case (1 Base, 2 Upside, 3 Downside) | D6: 1
B8: Transaction
B9: Unaffected share price | C9: ₹ | D9: 380
B10: Offer premium to unaffected | D10: 0.25
B11: Diluted shares | C11: crore shares | D11: 12
B12: Transaction fees (% of entry EV) | D12: 0.015
B13: Financing fees (% of debt raised) | D13: 0.02
B14: Financing fee amortisation period | C14: years | D14: 5
B15: Minimum operating cash | D15: 100
B16: Promoter / management rollover (% of equity purchase) | D16: 0.1
B17: Leverage scale (1.0 = tranche multiples below) | C17: x | D17: 1
B18: Excess cash swept to sweepable debt | D18: 1
B19: Holding period | C19: years | D19: 5
B20: Exit costs (% of exit EV) | D20: 0.01
B21: Management incentive pool (% of equity gain) | D21: 0.075
B22: Sponsor hurdle IRR | D22: 0.2
B23: Sponsor target MOIC | D23: 2.5
B25: Operating, tax and sensitivity shifts
B26: Corporate tax rate (s.115BAA: 22% + 10% surcharge + 4% cess) | D26: 0.2517
B27: Interest earned on cash | D27: 0.06
B28: Interest cap (% of tax EBITDA), s.94B | D28: 0.3
B29: Interest cap threshold (caught interest) | D29: 1
B30: Revenue growth shift (added every year) | D30: 0
B31: Gross / EBITDA margin shift (added every year) | D31: 0
B32: EBITDA haircut (proportional) | D32: 0
B34: Revolver and covenants
B35: Revolver commitment | D35: 150
B36: Revolver cash rate | D36: 0.09
B37: Revolver undrawn fee | D37: 0.0035
B38: Minimum interest cover (EBITDA / cash interest) | D38: 2.25
B39: Minimum DSCR ((EBITDA - capex - tax) / debt service) | D39: 1.15
B41: Exit multiple (EV / EBITDA)
B42: Base case | D42: 13.5
B43: Upside case | D43: 15.5
B44: Downside case | D44: 10.5
B45: Live exit multiple | D45: =CHOOSE(Case,$D$42,$D$43,$D$44) -> 13.5
B47: Operating drivers by case | C47: INR crore | G47: FY27E | H47: FY28E | I47: FY29E | J47: FY30E | K47: FY31E
...

Sheet IS
B2: Income statement
B3: Historical figures are inputs; projections follow the live case.
B5: Income statement | C5: INR crore | D5: FY24A | E5: FY25A | F5: FY26A | G5: FY27E | H5: FY28E | I5: FY29E | J5: FY30E | K5: FY31E
B6: Revenue | D6: 1920 | E6: 2150 | F6: 2400 | G6: =F6*(1+Inputs!G53+Growth_Shift) -> 2712 | H6: =G6*(1+Inputs!H53+Growth_Shift) -> 3064.56 | I6: =H6*(1+Inputs!I53+Growth_Shift) -> 3447.63 | J6: =I6*(1+Inputs!J53+Growth_Shift) -> 3861.3456 | K6: =J6*(1+Inputs!K53+Growth_Shift) -> 4305.4003
B7: Growth | E7: =E6/$D$6-1 -> 0.11979167 | F7: =F6/E6-1 -> 0.11627907 | G7: =G6/F6-1 -> 0.13 | H7: =H6/G6-1 -> 0.13 | I7: =I6/H6-1 -> 0.125 | J7: =J6/I6-1 -> 0.12 | K7: =K6/J6-1 -> 0.115
B8: Cost of goods sold | D8: 1133 | E8: 1258 | F8: 1392 | G8: =G6-G9 -> 1559.4 | H8: =H6-H9 -> 1746.7992 | I8: =I6-I9 -> 1947.9109 | J8: =J6-J9 -> 2162.3535 | K8: =K6-K9 -> 2411.0242
B9: Gross profit | D9: =$D$6-$D$8 -> 787 | E9: =E6-E8 -> 892 | F9: =F6-F8 -> 1008 | G9: =G6*(Inputs!G59+Margin_Shift) -> 1152.6 | H9: =H6*(Inputs!H59+Margin_Shift) -> 1317.7608 | I9: =I6*(Inputs!I59+Margin_Shift) -> 1499.719 | J9: =J6*(Inputs!J59+Margin_Shift) -> 1698.9921 | K9: =K6*(Inputs!K59+Margin_Shift) -> 1894.3762
B10: Gross margin | D10: =$D$9/$D$6 -> 0.40989583 | E10: =E9/E6 -> 0.41488372 | F10: =F9/F6 -> 0.42 | G10: =G9/G6 -> 0.425 | H10: =H9/H6 -> 0.43 | I10: =I9/I6 -> 0.435 | J10: =J9/J6 -> 0.44 | K10: =K9/K6 -> 0.44
B11: Operating expenses (ex D&A) | D11: 480 | E11: 538 | F11: 600 | G11: =G6*Inputs!G65+EBITDA_Haircut*(G9-G6*Inputs!G65) -> 678 | H11: =H6*Inputs!H65+EBITDA_Haircut*(H9-H6*Inputs!H65) -> 760.01088 | I11: =I6*Inputs!I65+EBITDA_Haircut*(I9-I6*Inputs!I65) -> 844.66935 | J11: =J6*Inputs!J65+EBITDA_Haircut*(J9-J6*Inputs!J65) -> 938.30698 | K11: =K6*Inputs!K65+EBITDA_Haircut*(K9-K6*Inputs!K65) -> 1033.2961
B12: EBITDA | D12: =$D$9-$D$11 -> 307 | E12: =E9-E11 -> 354 | F12: =F9-F11 -> 408 | G12: =G9-G11 -> 474.6 | H12: =H9-H11 -> 557.74992 | I12: =I9-I11 -> 655.0497 | J12: =J9-J11 -> 760.68508 | K12: =K9-K11 -> 861.08007
B13: EBITDA margin | D13: =$D$12/$D$6 -> 0.15989583 | E13: =E12/E6 -> 0.16465116 | F13: =F12/F6 -> 0.17 | G13: =G12/G6 -> 0.175 | H13: =H12/H6 -> 0.182 | I13: =I12/I6 -> 0.19 | J13: =J12/J6 -> 0.197 | K13: =K12/K6 -> 0.2
B14: Depreciation and amortisation | D14: 48 | E14: 53 | F14: 60 | G14: =G6*Inputs!G71 -> 67.8 | H14: =H6*Inputs!H71 -> 76.614 | I14: =I6*Inputs!I71 -> 86.19075 | J14: =J6*Inputs!J71 -> 96.53364 | K14: =K6*Inputs!K71 -> 107.63501
B15: EBIT | D15: =$D$12-$D$14 -> 259 | E15: =E12-E14 -> 301 | F15: =F12-F14 -> 348 | G15: =G12-G14 -> 406.8 | H15: =H12-H14 -> 481.13592 | I15: =I12-I14 -> 568.85895 | J15: =J12-J14 -> 664.15144 | K15: =K12-K14 -> 753.44506
B16: Other income / interest on cash | D16: 12 | E16: 14 | F16: 15 | G16: =Debt!G47 -> 6 | H16: =Debt!H47 -> 6 | I16: =Debt!I47 -> 6 | J16: =Debt!J47 -> 6 | K16: =Debt!K47 -> 23.395066
B17: Finance cost | D17: 22 | E17: 20 | F17: 18 | G17: =Debt!G46 -> 206.463 | H17: =Debt!H46 -> 200.70606 | I17: =Debt!I46 -> 188.9596 | J17: =Debt!J46 -> 169.17317 | K17: =Debt!K46 -> 167.77566
B18: Profit before tax | D18: =$D$15+$D$16-$D$17 -> 249 | E18: =E15+E16-E17 -> 295 | F18: =F15+F16-F17 -> 345 | G18: =G15+G16-G17 -> 206.337 | H18: =H15+H16-H17 -> 286.42986 | I18: =I15+I16-I17 -> 385.89935 | J18: =J15+J16-J17 -> 500.97828 | K18: =K15+K16-K17 -> 609.06447
B19: Tax | D19: 62.7 | E19: 74.3 | F19: 86.8 | G19: =G34 -> 65.968556 | H19: =H34 -> 78.400257 | I19: =I34 -> 93.133037 | J19: =J34 -> 109.75467 | K19: =K34 -> 153.30153
B20: Net income | D20: =$D$18-$D$19 -> 186.3 | E20: =E18-E19 -> 220.7 | F20: =F18-F19 -> 258.2 | G20: =G18-G19 -> 140.36844 | H20: =H18-H19 -> 208.0296 | I20: =I18-I19 -> 292.76631 | J20: =J18-J19 -> 391.22361 | K20: =K18-K19 -> 455.76294
B22: Tax schedule (interest limitation and losses) | C22: INR crore | F22: At close | G22: FY27E | H22: FY28E | I22: FY29E | J22: FY30E | K22: FY31E
B23: Interest expense for the cap (cash + PIK + revolver) | G23: =Debt!G42+Debt!G43+Debt!G20+Debt!G21 -> 199.935 | H23: =Debt!H42+Debt!H43+Debt!H20+Debt!H21 -> 194.17806 | I23: =Debt!I42+Debt!I43+Debt!I20+Debt!I21 -> 182.4316 | J23: =Debt!J42+Debt!J43+Debt!J20+Debt!J21 -> 162.64517 | K23: =Debt!K42+Debt!K43+Debt!K20+Debt!K21 -> 161.24766
B24: Tax EBITDA (EBITDA + interest income) | G24: =G12+G16 -> 480.6 | H24: =H12+H16 -> 563.74992 | I24: =I12+I16 -> 661.0497 | J24: =J12+J16 -> 766.68508 | K24: =K12+K16 -> 884.47513
B25: Interest cap | G25: =Cap_Pct*G24 -> 144.18 | H25: =Cap_Pct*H24 -> 169.12498 | I25: =Cap_Pct*I24 -> 198.31491 | J25: =Cap_Pct*J24 -> 230.00552 | K25: =Cap_Pct*K24 -> 265.34254
B26: Interest on caught debt | G26: =(Debt!G25+Debt!G26)*Inputs!$D$107+(Debt!G34+Debt!G35)*Inputs!$D$115 -> 142.8 | H26: =(Debt!H25+Debt!H26)*Inputs!$D$107+(Debt!H34+Debt!H35)*Inputs!$D$115 -> 147.084 | I26: =(Debt!I25+Debt!I26)*Inputs!$D$107+(Debt!I34+Debt!I35)*Inputs!$D$115 -> 151.49652 | J26: =(Debt!J25+Debt!J26)*Inputs!$D$107+(Debt!J34+Debt!J35)*Inputs!$D$115 -> 156.04142 | K26: =(Debt!K25+Debt!K26)*Inputs!$D$107+(Debt!K34+Debt!K35)*Inputs!$D$115 -> 160.72266
B27: Disallowed interest (carried forward) | G27: =IF(G26>Cap_Threshold,MIN(MAX(0,G23-G25),G26),0) -> 55.755 | H27: =IF(H26>Cap_Threshold,MIN(MAX(0,H23-H25),H26),0) -> 25.053085 | I27: =IF(I26>Cap_Threshold,MIN(MAX(0,I23-I25),I26),0) -> 0 | J27: =IF(J26>Cap_Threshold,MIN(MAX(0,J23-J25),J26),0) -> 0 | K27: =IF(K26>Cap_Threshold,MIN(MAX(0,K23-K25),K26),0) -> 0
B28: Carried-forward interest deducted | G28: =MIN(F29,MAX(0,G25-G23)) -> 0 | H28: =MIN(G29,MAX(0,H25-H23)) -> 0 | I28: =MIN(H29,MAX(0,I25-I23)) -> 15.883309 | J28: =MIN(I29,MAX(0,J25-J23)) -> 64.924776 | K28: =MIN(J29,MAX(0,K25-K23)) -> 0
B29: Disallowed interest carried forward (closing) | F29: 0 | G29: =F29+G27-G28 -> 55.755 | H29: =G29+H27-H28 -> 80.808085 | I29: =H29+I27-I28 -> 64.924776 | J29: =I29+J27-J28 -> 0 | K29: =J29+K27-K28 -> 0
B30: Taxable income before losses | G30: =G18+G27-G28 -> 262.092 | H30: =H18+H27-H28 -> 311.48294 | I30: =I18+I27-I28 -> 370.01604 | J30: =J18+J27-J28 -> 436.0535 | K30: =K18+K27-K28 -> 609.06447
B31: Tax losses used | G31: =MIN(F32,MAX(0,G30)) -> 0 | H31: =MIN(G32,MAX(0,H30)) -> 0 | I31: =MIN(H32,MAX(0,I30)) -> 0 | J31: =MIN(I32,MAX(0,J30)) -> 0 | K31: =MIN(J32,MAX(0,K30)) -> 0
B32: Tax losses carried forward (closing) | F32: 0 | G32: =F32-G31+MAX(0,-G30) -> 0 | H32: =G32-H31+MAX(0,-H30) -> 0 | I32: =H32-I31+MAX(0,-I30) -> 0 | J32: =I32-J31+MAX(0,-J30) -> 0 | K32: =J32-K31+MAX(0,-K30) -> 0
B33: Taxable income | G33: =MAX(0,G30-G31) -> 262.092 | H33: =MAX(0,H30-H31) -> 311.48294 | I33: =MAX(0,I30-I31) -> 370.01604 | J33: =MAX(0,J30-J31) -> 436.0535 | K33: =MAX(0,K30-K31) -> 609.06447
B34: Tax at the corporate rate | G34: =G33*Tax_Rate -> 65.968556 | H34: =H33*Tax_Rate -> 78.400257 | I34: =I33*Tax_Rate -> 93.133037 | J34: =J33*Tax_Rate -> 109.75467 | K34: =K33*Tax_Rate -> 153.30153
B36: s.94B of the Income-tax Act, 1961 (carried into the Income-tax Act, 2025) caps deductible interest on debt from, or guaranteed by, non-resident associated enterprises at 30% of EBITDA. Confirm applicability with tax counsel.

Sheet BS
B2: Balance sheet
B3: FY26A is reported; the deal adjusts it to the pro forma balance sheet at close.
B5: Balance sheet | C5: INR crore | D5: FY26A | E5: Adjustments | F5: Pro forma | G5: FY27E | H5: FY28E | I5: FY29E | J5: FY30E | K5: FY31E
B6: Assets
B7: Cash | D7: 260 | E7: =Min_Cash-D7 -> -160 | F7: =D7+E7 -> 100 | G7: =CF!G20 -> 100 | H7: =CF!H20 -> 100 | I7: =CF!I20 -> 100 | J7: =CF!J20 -> 389.91776 | K7: =CF!K20 -> 803.69117
B8: Trade receivables | D8: 197 | F8: =D8+E8 -> 197 | G8: =IS!G6*Inputs!G83/365 -> 222.90411 | H8: =IS!H6*Inputs!H83/365 -> 251.88164 | I8: =IS!I6*Inputs!I83/365 -> 283.36685 | J8: =IS!J6*Inputs!J83/365 -> 317.37087 | K8: =IS!K6*Inputs!K83/365 -> 353.86852
B9: Inventory | D9: 229 | F9: =D9+E9 -> 229 | G9: =IS!G8*Inputs!G89/365 -> 256.33973 | H9: =IS!H8*Inputs!H89/365 -> 287.14507 | I9: =IS!I8*Inputs!I89/365 -> 320.20454 | J9: =IS!J8*Inputs!J89/365 -> 355.45538 | K9: =IS!K8*Inputs!K89/365 -> 396.33274
B10: Other current assets | D10: 80 | F10: =D10+E10 -> 80 | G10: =F10 -> 80 | H10: =G10 -> 80 | I10: =H10 -> 80 | J10: =I10 -> 80 | K10: =J10 -> 80
B11: Property, plant and equipment | D11: 900 | F11: =D11+E11 -> 900 | G11: =F11-CF!G12-IS!G14 -> 940.68 | H11: =G11-CF!H12-IS!H14 -> 980.51928 | I11: =H11-CF!I12-IS!I14 -> 1014.9956 | J11: =I11-CF!J12-IS!J14 -> 1053.609 | K11: =J11-CF!K12-IS!K14 -> 1096.663
B12: Intangibles | D12: 150 | F12: =D12+E12 -> 150 | G12: =F12 -> 150 | H12: =G12 -> 150 | I12: =H12 -> 150 | J12: =I12 -> 150 | K12: =J12 -> 150
B13: Goodwill from the transaction | D13: 0 | E13: =Deal!$D$44 -> 4424 | F13: =D13+E13 -> 4424 | G13: =F13 -> 4424 | H13: =G13 -> 4424 | I13: =H13 -> 4424 | J13: =I13 -> 4424 | K13: =J13 -> 4424
B14: Other non-current assets | D14: 60 | F14: =D14+E14 -> 60 | G14: =F14 -> 60 | H14: =G14 -> 60 | I14: =H14 -> 60 | J14: =I14 -> 60 | K14: =J14 -> 60
B15: Deferred financing fees | D15: 0 | E15: =Deal!$D$20 -> 32.64 | F15: =D15+E15 -> 32.64 | G15: =F15-Debt!G45 -> 26.112 | H15: =G15-Debt!H45 -> 19.584 | I15: =H15-Debt!I45 -> 13.056 | J15: =I15-Debt!J45 -> 6.528 | K15: =J15-Debt!K45 -> 1.7763568e-15
B16: Total assets | D16: =D7+D8+D9+D10+D11+D12+D13+D14+D15 -> 1876 | E16: =E7+E8+E9+E10+E11+E12+E13+E14+E15 -> 4296.64 | F16: =F7+F8+F9+F10+F11+F12+F13+F14+F15 -> 6172.64 | G16: =G7+G8+G9+G10+G11+G12+G13+G14+G15 -> 6260.0358 | H16: =H7+H8+H9+H10+H11+H12+H13+H14+H15 -> 6353.13 | I16: =I7+I8+I9+I10+I11+I12+I13+I14+I15 -> 6445.623 | J16: =J7+J8+J9+J10+J11+J12+J13+J14+J15 -> 6836.881 | K16: =K7+K8+K9+K10+K11+K12+K13+K14+K15 -> 7364.5555
B18: Liabilities and equity
B19: Trade payables | D19: 210 | F19: =D19+E19 -> 210 | G19: =IS!G8*Inputs!G95/365 -> 234.97808 | H19: =IS!H8*Inputs!H95/365 -> 263.21632 | I19: =IS!I8*Inputs!I95/365 -> 293.52083 | J19: =IS!J8*Inputs!J95/365 -> 325.83409 | K19: =IS!K8*Inputs!K95/365 -> 363.30502
B20: Other current liabilities | D20: 120 | F20: =D20+E20 -> 120 | G20: =F20 -> 120 | H20: =G20 -> 120 | I20: =H20 -> 120 | J20: =I20 -> 120 | K20: =J20 -> 120
B21: Revolver | D21: 0 | F21: =D21+E21 -> 0 | G21: =Debt!G19 -> 0 | H21: =Debt!H19 -> 0 | I21: =Debt!I19 -> 0 | J21: =Debt!J19 -> 0 | K21: =Debt!K19 -> 0
B22: Existing debt (refinanced at close) | D22: 200 | E22: =-D22 -> -200 | F22: =D22+E22 -> 0 | G22: =F22 -> 0 | H22: =G22 -> 0 | I22: =H22 -> 0 | J22: =I22 -> 0 | K22: =J22 -> 0
B23: OpCo senior term loan | D23: 0 | E23: =Deal!$D$15 -> 612 | F23: =D23+E23 -> 612 | G23: =Debt!G30 -> 503.44931 | H23: =Debt!H30 -> 328.75763 | I23: =Debt!I30 -> 65.716244 | J23: =Debt!J30 -> 0 | K23: =Debt!K30 -> 0
B24: HoldCo NCDs (private credit) | D24: 0 | E24: =Deal!$D$16 -> 1020 | F24: =D24+E24 -> 1020 | G24: =Debt!G39 -> 1050.6 | H24: =Debt!H39 -> 1082.118 | I24: =Debt!I39 -> 1114.5815 | J24: =Debt!J39 -> 1148.019 | K24: =Debt!K39 -> 1182.4596
B25: Other non-current liabilities | D25: 70 | F25: =D25+E25 -> 70 | G25: =F25 -> 70 | H25: =G25 -> 70 | I25: =H25 -> 70 | J25: =I25 -> 70 | K25: =J25 -> 70
B26: Shareholders' equity | D26: 1276 | E26: =Deal!$D$41-Deal!$D$19-D26 -> 2864.64 | F26: =D26+E26 -> 4140.64 | G26: =F26+IS!G20 -> 4281.0084 | H26: =G26+IS!H20 -> 4489.038 | I26: =H26+IS!I20 -> 4781.8044 | J26: =I26+IS!J20 -> 5173.028 | K26: =J26+IS!K20 -> 5628.7909
B27: Total liabilities and equity | D27: =D19+D20+D21+D22+D23+D24+D25+D26 -> 1876 | E27: =E19+E20+E21+E22+E23+E24+E25+E26 -> 4296.64 | F27: =F19+F20+F21+F22+F23+F24+F25+F26 -> 6172.64 | G27: =G19+G20+G21+G22+G23+G24+G25+G26 -> 6260.0358 | H27: =H19+H20+H21+H22+H23+H24+H25+H26 -> 6353.13 | I27: =I19+I20+I21+I22+I23+I24+I25+I26 -> 6445.623 | J27: =J19+J20+J21+J22+J23+J24+J25+J26 -> 6836.881 | K27: =K19+K20+K21+K22+K23+K24+K25+K26 -> 7364.5555
B28: Balance check (assets - liabilities and equity) | D28: =ROUND(D16-D27,6) -> 0 | F28: =ROUND(F16-F27,6) -> 0 | G28: =ROUND(G16-G27,6) -> 0 | H28: =ROUND(H16-H27,6) -> 0 | I28: =ROUND(I16-I27,6) -> 0 | J28: =ROUND(J16-J27,6) -> 0 | K28: =ROUND(K16-K27,6) -> 0
B30: Memo
B31: Trade working capital (receivables + inventory - payables) | F31: =F8+F9-F19 -> 216 | G31: =G8+G9-G19 -> 244.26575 | H31: =H8+H9-H19 -> 275.8104 | I31: =I8+I9-I19 -> 310.05056 | J31: =J8+J9-J19 -> 346.99215 | K31: =K8+K9-K19 -> 386.89625
B32: Total debt | G32: =G21+G22+G23+G24 -> 1554.0493 | H32: =H21+H22+H23+H24 -> 1410.8756 | I32: =I21+I22+I23+I24 -> 1180.2978 | J32: =J21+J22+J23+J24 -> 1148.019 | K32: =K21+K22+K23+K24 -> 1182.4596
B33: Net debt | G33: =G32-G7 -> 1454.0493 | H33: =H32-H7 -> 1310.8756 | I33: =I32-I7 -> 1080.2978 | J33: =J32-J7 -> 758.10122 | K33: =K32-K7 -> 378.76838

Sheet CF
B2: Cash flow statement
B3: Indirect method. Closing cash feeds the balance sheet.
B5: Cash flow statement | C5: INR crore | G5: FY27E | H5: FY28E | I5: FY29E | J5: FY30E | K5: FY31E
B6: Net income | G6: =IS!G20 -> 140.36844 | H6: =IS!H20 -> 208.0296 | I6: =IS!I20 -> 292.76631 | J6: =IS!J20 -> 391.22361 | K6: =IS!K20 -> 455.76294
B7: Depreciation and amortisation | G7: =IS!G14 -> 67.8 | H7: =IS!H14 -> 76.614 | I7: =IS!I14 -> 86.19075 | J7: =IS!J14 -> 96.53364 | K7: =IS!K14 -> 107.63501
B8: PIK interest (non-cash) | G8: =Debt!G43 -> 30.6 | H8: =Debt!H43 -> 31.518 | I8: =Debt!I43 -> 32.46354 | J8: =Debt!J43 -> 33.437446 | K8: =Debt!K43 -> 34.44057
B9: Financing fee amortisation (non-cash) | G9: =Debt!G45 -> 6.528 | H9: =Debt!H45 -> 6.528 | I9: =Debt!I45 -> 6.528 | J9: =Debt!J45 -> 6.528 | K9: =Debt!K45 -> 6.528
B10: (Increase) / decrease in working capital | G10: =-(BS!G31-BS!F31) -> -28.265753 | H10: =-(BS!H31-BS!G31) -> -31.544647 | I10: =-(BS!I31-BS!H31) -> -34.240161 | J10: =-(BS!J31-BS!I31) -> -36.941592 | K10: =-(BS!K31-BS!J31) -> -39.904098
B11: Cash flow from operations | G11: =G6+G7+G8+G9+G10 -> 217.03069 | H11: =H6+H7+H8+H9+H10 -> 291.14496 | I11: =I6+I7+I8+I9+I10 -> 383.70844 | J11: =J6+J7+J8+J9+J10 -> 490.7811 | K11: =K6+K7+K8+K9+K10 -> 564.46242
B12: Capital expenditure | G12: =-IS!G6*Inputs!G77 -> -108.48 | H12: =-IS!H6*Inputs!H77 -> -116.45328 | I12: =-IS!I6*Inputs!I77 -> -120.66705 | J12: =-IS!J6*Inputs!J77 -> -135.1471 | K12: =-IS!K6*Inputs!K77 -> -150.68901
B13: Cash flow from investing | G13: =G12 -> -108.48 | H13: =H12 -> -116.45328 | I13: =I12 -> -120.66705 | J13: =J12 -> -135.1471 | K13: =K12 -> -150.68901
B14: Revolver draw / (repayment) | G14: =Debt!G12 -> 0 | H14: =Debt!H12 -> 0 | I14: =Debt!I12 -> 0 | J14: =Debt!J12 -> 0 | K14: =Debt!K12 -> 0
B15: Scheduled debt repayment | G15: =-Debt!G9 -> -61.2 | H15: =-Debt!H9 -> -61.2 | I15: =-Debt!I9 -> -91.8 | J15: =-Debt!J9 -> -65.716244 | K15: =-Debt!K9 -> 0
B16: Cash sweep prepayment | G16: =-Debt!G44 -> -47.35069 | H16: =-Debt!H44 -> -113.49168 | I16: =-Debt!I44 -> -171.24139 | J16: =-Debt!J44 -> 0 | K16: =-Debt!K44 -> 0
B17: Cash flow from financing | G17: =G14+G15+G16 -> -108.55069 | H17: =H14+H15+H16 -> -174.69168 | I17: =I14+I15+I16 -> -263.04139 | J17: =J14+J15+J16 -> -65.716244 | K17: =K14+K15+K16 -> 0
B18: Net change in cash | G18: =G11+G13+G17 -> -1.4210855e-14 | H18: =H11+H13+H17 -> 0 | I18: =I11+I13+I17 -> 0 | J18: =J11+J13+J17 -> 289.91776 | K18: =K11+K13+K17 -> 413.77341
B19: Opening cash | G19: =BS!F7 -> 100 | H19: =BS!G7 -> 100 | I19: =BS!H7 -> 100 | J19: =BS!I7 -> 100 | K19: =BS!J7 -> 389.91776
B20: Closing cash | G20: =G19+G18 -> 100 | H20: =H19+H18 -> 100 | I20: =I19+I18 -> 100 | J20: =J19+J18 -> 389.91776 | K20: =K19+K18 -> 803.69117

Sheet Debt
B2: Debt schedule and cash sweep
B3: Interest accrues on opening balances (no circularity). The revolver funds shortfalls; excess cash repays sweepable debt in order.
B5: Cash available for debt service | C5: INR crore | G5: FY27E | H5: FY28E | I5: FY29E | J5: FY30E | K5: FY31E
B6: Opening cash | G6: =BS!F7 -> 100 | H6: =BS!G7 -> 100 | I6: =BS!H7 -> 100 | J6: =BS!I7 -> 100 | K6: =BS!J7 -> 389.91776
B7: Cash flow from operations | G7: =CF!G11 -> 217.03069 | H7: =CF!H11 -> 291.14496 | I7: =CF!I11 -> 383.70844 | J7: =CF!J11 -> 490.7811 | K7: =CF!K11 -> 564.46242
B8: Cash flow from investing | G8: =CF!G13 -> -108.48 | H8: =CF!H13 -> -116.45328 | I8: =CF!I13 -> -120.66705 | J8: =CF!J13 -> -135.1471 | K8: =CF!K13 -> -150.68901
B9: Scheduled repayments | G9: =G27+G36 -> 61.2 | H9: =H27+H36 -> 61.2 | I9: =I27+I36 -> 91.8 | J9: =J27+J36 -> 65.716244 | K9: =K27+K36 -> 0
B10: Minimum cash | G10: =Min_Cash -> 100 | H10: =Min_Cash -> 100 | I10: =Min_Cash -> 100 | J10: =Min_Cash -> 100 | K10: =Min_Cash -> 100
B11: Cash available after scheduled debt service | G11: =G6+G7+G8-G9-G10 -> 47.35069 | H11: =H6+H7+H8-H9-H10 -> 113.49168 | I11: =I6+I7+I8-I9-I10 -> 171.24139 | J11: =J6+J7+J8-J9-J10 -> 289.91776 | K11: =K6+K7+K8-K9-K10 -> 703.69117
B12: Revolver draw / (repayment) | G12: =MIN(MAX(-G11,-G17),Rev_Commitment-G17) -> 0 | H12: =MIN(MAX(-H11,-H17),Rev_Commitment-H17) -> 0 | I12: =MIN(MAX(-I11,-I17),Rev_Commitment-I17) -> 0 | J12: =MIN(MAX(-J11,-J17),Rev_Commitment-J17) -> 0 | K12: =MIN(MAX(-K11,-K17),Rev_Commitment-K17) -> 0
B13: Cash after revolver | G13: =G11+G12 -> 47.35069 | H13: =H11+H12 -> 113.49168 | I13: =I11+I12 -> 171.24139 | J13: =J11+J12 -> 289.91776 | K13: =K11+K12 -> 703.69117
B14: Cash available for the sweep | G14: =MAX(0,G13)*Sweep_Pct -> 47.35069 | H14: =MAX(0,H13)*Sweep_Pct -> 113.49168 | I14: =MAX(0,I13)*Sweep_Pct -> 171.24139 | J14: =MAX(0,J13)*Sweep_Pct -> 289.91776 | K14: =MAX(0,K13)*Sweep_Pct -> 703.69117
B16: Revolver
B17: Opening balance | G17: =BS!F21 -> 0 | H17: =BS!G21 -> 0 | I17: =BS!H21 -> 0 | J17: =BS!I21 -> 0 | K17: =BS!J21 -> 0
B18: Draw / (repayment) | G18: =G12 -> 0 | H18: =H12 -> 0 | I18: =I12 -> 0 | J18: =J12 -> 0 | K18: =K12 -> 0
B19: Closing balance | G19: =G17+G18 -> 0 | H19: =H17+H18 -> 0 | I19: =I17+I18 -> 0 | J19: =J17+J18 -> 0 | K19: =K17+K18 -> 0
B20: Interest | G20: =G17*Rev_Rate -> 0 | H20: =H17*Rev_Rate -> 0 | I20: =I17*Rev_Rate -> 0 | J20: =J17*Rev_Rate -> 0 | K20: =K17*Rev_Rate -> 0
B21: Undrawn commitment fee | G21: =(Rev_Commitment-G17)*Rev_Undrawn_Fee -> 0.525 | H21: =(Rev_Commitment-H17)*Rev_Undrawn_Fee -> 0.525 | I21: =(Rev_Commitment-I17)*Rev_Undrawn_Fee -> 0.525 | J21: =(Rev_Commitment-J17)*Rev_Undrawn_Fee -> 0.525 | K21: =(Rev_Commitment-K17)*Rev_Undrawn_Fee -> 0.525
B23: OpCo senior term loan (amortizing)
B24: Opening balance | G24: =BS!F23 -> 612 | H24: =BS!G23 -> 503.44931 | I24: =BS!H23 -> 328.75763 | J24: =BS!I23 -> 65.716244 | K24: =BS!J23 -> 0
B25: Cash interest | G25: =G24*Inputs!$D$104 -> 56.61 | H25: =H24*Inputs!$D$104 -> 46.569061 | I25: =I24*Inputs!$D$104 -> 30.410081 | J25: =J24*Inputs!$D$104 -> 6.0787526 | K25: =K24*Inputs!$D$104 -> 0
B26: PIK interest | G26: =G24*Inputs!$D$105 -> 0 | H26: =H24*Inputs!$D$105 -> 0 | I26: =I24*Inputs!$D$105 -> 0 | J26: =J24*Inputs!$D$105 -> 0 | K26: =K24*Inputs!$D$105 -> 0
B27: Scheduled repayment | G27: =MIN(G24+G26,Inputs!G108*Deal!$D$15) -> 61.2 | H27: =MIN(H24+H26,Inputs!H108*Deal!$D$15) -> 61.2 | I27: =MIN(I24+I26,Inputs!I108*Deal!$D$15) -> 91.8 | J27: =MIN(J24+J26,Inputs!J108*Deal!$D$15) -> 65.716244 | K27: =MIN(K24+K26,Inputs!K108*Deal!$D$15) -> 0
B28: Sweep cash still available | G28: =G14 -> 47.35069 | H28: =H14 -> 113.49168 | I28: =I14 -> 171.24139 | J28: =J14 -> 289.91776 | K28: =K14 -> 703.69117
B29: Sweep prepayment | G29: =IF(Inputs!$D$106=1,MIN(G28,G24+G26-G27),0) -> 47.35069 | H29: =IF(Inputs!$D$106=1,MIN(H28,H24+H26-H27),0) -> 113.49168 | I29: =IF(Inputs!$D$106=1,MIN(I28,I24+I26-I27),0) -> 171.24139 | J29: =IF(Inputs!$D$106=1,MIN(J28,J24+J26-J27),0) -> 0 | K29: =IF(Inputs!$D$106=1,MIN(K28,K24+K26-K27),0) -> 0
B30: Closing balance | G30: =G24+G26-G27-G29 -> 503.44931 | H30: =H24+H26-H27-H29 -> 328.75763 | I30: =I24+I26-I27-I29 -> 65.716244 | J30: =J24+J26-J27-J29 -> 0 | K30: =K24+K26-K27-K29 -> 0
B32: HoldCo NCDs (private credit) (bullet)
B33: Opening balance | G33: =BS!F24 -> 1020 | H33: =BS!G24 -> 1050.6 | I33: =BS!H24 -> 1082.118 | J33: =BS!I24 -> 1114.5815 | K33: =BS!J24 -> 1148.019
B34: Cash interest | G34: =G33*Inputs!$D$112 -> 112.2 | H34: =H33*Inputs!$D$112 -> 115.566 | I34: =I33*Inputs!$D$112 -> 119.03298 | J34: =J33*Inputs!$D$112 -> 122.60397 | K34: =K33*Inputs!$D$112 -> 126.28209
B35: PIK interest | G35: =G33*Inputs!$D$113 -> 30.6 | H35: =H33*Inputs!$D$113 -> 31.518 | I35: =I33*Inputs!$D$113 -> 32.46354 | J35: =J33*Inputs!$D$113 -> 33.437446 | K35: =K33*Inputs!$D$113 -> 34.44057
B36: Scheduled repayment | G36: =MIN(G33+G35,Inputs!G116*Deal!$D$16) -> 0 | H36: =MIN(H33+H35,Inputs!H116*Deal!$D$16) -> 0 | I36: =MIN(I33+I35,Inputs!I116*Deal!$D$16) -> 0 | J36: =MIN(J33+J35,Inputs!J116*Deal!$D$16) -> 0 | K36: =MIN(K33+K35,Inputs!K116*Deal!$D$16) -> 0
B37: Sweep cash still available | G37: =G28-G29 -> 0 | H37: =H28-H29 -> 0 | I37: =I28-I29 -> 0 | J37: =J28-J29 -> 289.91776 | K37: =K28-K29 -> 703.69117
B38: Sweep prepayment | G38: =IF(Inputs!$D$114=1,MIN(G37,G33+G35-G36),0) -> 0 | H38: =IF(Inputs!$D$114=1,MIN(H37,H33+H35-H36),0) -> 0 | I38: =IF(Inputs!$D$114=1,MIN(I37,I33+I35-I36),0) -> 0 | J38: =IF(Inputs!$D$114=1,MIN(J37,J33+J35-J36),0) -> 0 | K38: =IF(Inputs!$D$114=1,MIN(K37,K33+K35-K36),0) -> 0
B39: Closing balance | G39: =G33+G35-G36-G38 -> 1050.6 | H39: =H33+H35-H36-H38 -> 1082.118 | I39: =I33+I35-I36-I38 -> 1114.5815 | J39: =J33+J35-J36-J38 -> 1148.019 | K39: =K33+K35-K36-K38 -> 1182.4596
B41: Interest summary
B42: Cash interest on term debt | G42: =G25+G34 -> 168.81 | H42: =H25+H34 -> 162.13506 | I42: =I25+I34 -> 149.44306 | J42: =J25+J34 -> 128.68272 | K42: =K25+K34 -> 126.28209
B43: PIK interest | G43: =G26+G35 -> 30.6 | H43: =H26+H35 -> 31.518 | I43: =I26+I35 -> 32.46354 | J43: =J26+J35 -> 33.437446 | K43: =K26+K35 -> 34.44057
B44: Total sweep prepayment | G44: =G29+G38 -> 47.35069 | H44: =H29+H38 -> 113.49168 | I44: =I29+I38 -> 171.24139 | J44: =J29+J38 -> 0 | K44: =K29+K38 -> 0
B45: Financing fee amortisation | G45: =MIN(BS!F15,Deal!$D$20/Fee_Amort_Years) -> 6.528 | H45: =MIN(BS!G15,Deal!$D$20/Fee_Amort_Years) -> 6.528 | I45: =MIN(BS!H15,Deal!$D$20/Fee_Amort_Years) -> 6.528 | J45: =MIN(BS!I15,Deal!$D$20/Fee_Amort_Years) -> 6.528 | K45: =MIN(BS!J15,Deal!$D$20/Fee_Amort_Years) -> 6.528
B46: Finance cost (to income statement) | G46: =G42+G43+G20+G21+G45 -> 206.463 | H46: =H42+H43+H20+H21+H45 -> 200.70606 | I46: =I42+I43+I20+I21+I45 -> 188.9596 | J46: =J42+J43+J20+J21+J45 -> 169.17317 | K46: =K42+K43+K20+K21+K45 -> 167.77566
...

Sheet Deal
B2: Transaction: sources and uses
B3: Assumed close on the FY26 balance sheet date. Sponsor equity is the balancing source.
B5: Purchase price
B6: Offer price per share | D6: =Unaffected_Price*(1+Offer_Premium) -> 475
B7: Equity purchase price | D7: =$D$6*Diluted_Shares -> 5700
B8: Plus: existing debt | D8: =BS!$D$22 -> 200
B9: Less: existing cash | D9: =BS!$D$7 -> 260
B10: Entry enterprise value | D10: =$D$7+$D$8-$D$9 -> 5640
B11: LTM EBITDA (FY26A) | D11: =IS!$F$12 -> 408
B12: Entry EV / LTM EBITDA | D12: =$D$10/$D$11 -> 13.823529
B14: Debt raised
B15: OpCo senior term loan | D15: =Inputs!$D$103*Leverage_Scale*$D$11 -> 612
B16: HoldCo NCDs (private credit) | D16: =Inputs!$D$111*Leverage_Scale*$D$11 -> 1020
B17: Total debt raised | D17: =$D$15+$D$16 -> 1632
B18: Total debt / LTM EBITDA | D18: =$D$17/$D$11 -> 4
B19: Transaction fees | D19: =Txn_Fee_Pct*$D$10 -> 84.6
B20: Financing fees (capitalised, amortised) | D20: =Fin_Fee_Pct*$D$17 -> 32.64
B21: Existing cash used (above minimum cash) | D21: =$D$9-Min_Cash -> 160
B22: Rollover equity | D22: =Rollover_Pct*$D$7 -> 570
B24: Uses
B25: Purchase of equity | D25: =$D$7 -> 5700
B26: Refinance existing debt | D26: =$D$8 -> 200
B27: Transaction fees | D27: =$D$19 -> 84.6
B28: Financing fees | D28: =$D$20 -> 32.64
B29: Total uses | D29: =$D$25+$D$26+$D$27+$D$28 -> 6017.24
B31: Sources
B32: OpCo senior term loan | D32: =$D$15 -> 612
B33: HoldCo NCDs (private credit) | D33: =$D$16 -> 1020
B34: Existing cash used | D34: =$D$21 -> 160
B35: Rollover equity | D35: =$D$22 -> 570
B36: Sponsor equity (plug) | D36: =$D$29-$D$17-$D$22-$D$21 -> 3655.24
B37: Total sources | D37: =$D$32+$D$33+$D$34+$D$35+$D$36 -> 6017.24
B38: Sources - uses | D38: =$D$37-$D$29 -> 0
B40: Equity and goodwill
B41: Total equity (sponsor + rollover) | D41: =$D$36+$D$22 -> 4225.24
B42: Equity contribution (% of capitalisation) | D42: =$D$41/($D$41+$D$17) -> 0.72137047
B43: Net debt at close | D43: =$D$17-Min_Cash -> 1532
B44: Goodwill (equity price - book equity; no PPA write-ups) | D44: =$D$7-BS!$D$26 -> 4424

Sheet Returns
B2: Returns, value creation and covenants
B3: Exit at the live multiple in the holding-period year.
B5: Exit
B6: Exit EV / EBITDA | D6: =Exit_Multiple -> 13.5
B7: Exit-year EBITDA | D7: =INDEX(IS!$G$12:$K$12,Holding_Years) -> 861.08007
B8: Exit enterprise value | D8: =$D$6*$D$7 -> 11624.581
B9: Exit costs | D9: =Exit_Cost_Pct*$D$8 -> 116.24581
B10: Net debt at exit | D10: =INDEX(BS!$G$33:$K$33,Holding_Years) -> 378.76838
B11: Equity value at exit | D11: =$D$8-$D$9-$D$10 -> 11129.567
B12: Equity invested (sponsor + rollover) | D12: =Deal!$D$41 -> 4225.24
B13: Management incentive pool | D13: =MIP_Pct*MAX(0,$D$11-$D$12) -> 517.82451
B14: Sponsor ownership | D14: =Deal!$D$36/$D$12 -> 0.86509642
B15: Sponsor proceeds | D15: =MAX(0,$D$11-$D$13)*$D$14 -> 9180.1802
B16: Sponsor MOIC | D16: =$D$15/Deal!$D$36 -> 2.5115123
B18: Sponsor cash flows | C18: INR crore | F18: Close | G18: FY27E | H18: FY28E | I18: FY29E | J18: FY30E | K18: FY31E
B19: Sponsor equity cash flow | F19: =-Deal!$D$36 -> -3655.24 | G19: =IF(1=Holding_Years,$D$15,0) -> 0 | H19: =IF(2=Holding_Years,$D$15,0) -> 0 | I19: =IF(3=Holding_Years,$D$15,0) -> 0 | J19: =IF(4=Holding_Years,$D$15,0) -> 0 | K19: =IF(5=Holding_Years,$D$15,0) -> 9180.1802
B20: Sponsor IRR | D20: =IF($D$15>0,IRR($F$19:$K$19),-1) -> 0.20222862
B22: Value-creation bridge (total equity)
B23: EBITDA growth at the entry multiple | D23: =($D$7-Deal!$D$11)*Deal!$D$12 -> 6263.1657
B24: Multiple expansion / (contraction) | D24: =($D$6-Deal!$D$12)*$D$7 -> -278.58473
B25: Net debt paydown | D25: =Deal!$D$43-$D$10 -> 1153.2316
B26: Fees and exit costs | D26: =-(Deal!$D$19+Deal!$D$20+$D$9) -> -233.48581
B27: Total equity value created | D27: =$D$23+$D$24+$D$25+$D$26 -> 6904.3267
B28: Check: bridge - (exit equity - invested) | D28: =$D$27-($D$11-$D$12) -> 2.7284841e-12
B30: Returns by exit year (live exit multiple) | C30: INR crore | G30: FY27E | H30: FY28E | I30: FY29E | J30: FY30E | K30: FY31E
B31: Years held | G31: 1 | H31: 2 | I31: 3 | J31: 4 | K31: 5
B32: Exit EV | G32: =Exit_Multiple*IS!G12 -> 6407.1 | H32: =Exit_Multiple*IS!H12 -> 7529.6239 | I32: =Exit_Multiple*IS!I12 -> 8843.1709 | J32: =Exit_Multiple*IS!J12 -> 10269.249 | K32: =Exit_Multiple*IS!K12 -> 11624.581
B33: Exit equity | G33: =G32*(1-Exit_Cost_Pct)-BS!G33 -> 4888.9797 | H33: =H32*(1-Exit_Cost_Pct)-BS!H33 -> 6143.452 | I33: =I32*(1-Exit_Cost_Pct)-BS!I33 -> 7674.4415 | J33: =J32*(1-Exit_Cost_Pct)-BS!J33 -> 9408.4549 | K33: =K32*(1-Exit_Cost_Pct)-BS!K33 -> 11129.567
B34: Sponsor proceeds | G34: =MAX(0,G33-MIP_Pct*MAX(0,G33-$D$12))*$D$14 -> 4186.3739 | H34: =MAX(0,H33-MIP_Pct*MAX(0,H33-$D$12))*$D$14 -> 5190.2205 | I34: =MAX(0,I33-MIP_Pct*MAX(0,I33-$D$12))*$D$14 -> 6415.3399 | J34: =MAX(0,J33-MIP_Pct*MAX(0,J33-$D$12))*$D$14 -> 7802.9221 | K34: =MAX(0,K33-MIP_Pct*MAX(0,K33-$D$12))*$D$14 -> 9180.1802
B35: MOIC | G35: =G34/Deal!$D$36 -> 1.1453075 | H35: =H34/Deal!$D$36 -> 1.4199397 | I35: =I34/Deal!$D$36 -> 1.7551077 | J35: =J34/Deal!$D$36 -> 2.1347222 | K35: =K34/Deal!$D$36 -> 2.5115123
B36: IRR | G36: =IF(G34>0,G35^(1/G31)-1,-1) -> 0.14530754 | H36: =IF(H34>0,H35^(1/H31)-1,-1) -> 0.19161224 | I36: =IF(I34>0,I35^(1/I31)-1,-1) -> 0.20624241 | J36: =IF(J34>0,J35^(1/J31)-1,-1) -> 0.20874682 | K36: =IF(K34>0,K35^(1/K31)-1,-1) -> 0.20222862
B38: Covenant tests | C38: INR crore | G38: FY27E | H38: FY28E | I38: FY29E | J38: FY30E | K38: FY31E
B39: EBITDA | G39: =IS!G12 -> 474.6 | H39: =IS!H12 -> 557.74992 | I39: =IS!I12 -> 655.0497 | J39: =IS!J12 -> 760.68508 | K39: =IS!K12 -> 861.08007
B40: Net debt | G40: =BS!G33 -> 1454.0493 | H40: =BS!H33 -> 1310.8756 | I40: =BS!I33 -> 1080.2978 | J40: =BS!J33 -> 758.10122 | K40: =BS!K33 -> 378.76838
B41: Net debt / EBITDA | G41: =G40/G39 -> 3.0637364 | H41: =H40/H39 -> 2.3502928 | I41: =I40/I39 -> 1.6491845 | J41: =J40/J39 -> 0.99660324 | K41: =K40/K39 -> 0.43987591
B42: Maximum | G42: =Inputs!G98 -> 4 | H42: =Inputs!H98 -> 3.5 | I42: =Inputs!I98 -> 3 | J42: =Inputs!J98 -> 2.75 | K42: =Inputs!K98 -> 2.5
B43: Cash interest (term debt + revolver + fees) | G43: =Debt!G42+Debt!G20+Debt!G21 -> 169.335 | H43: =Debt!H42+Debt!H20+Debt!H21 -> 162.66006 | I43: =Debt!I42+Debt!I20+Debt!I21 -> 149.96806 | J43: =Debt!J42+Debt!J20+Debt!J21 -> 129.20772 | K43: =Debt!K42+Debt!K20+Debt!K21 -> 126.80709
B44: Interest cover (EBITDA / cash interest) | G44: =G39/G43 -> 2.8027283 | H44: =H39/H43 -> 3.4289297 | I44: =I39/I43 -> 4.367928 | J44: =J39/J43 -> 5.8873036 | K44: =K39/K43 -> 6.7904727
B45: Debt service (cash interest + scheduled repayment) | G45: =G43+Debt!G9 -> 230.535 | H45: =H43+Debt!H9 -> 223.86006 | I45: =I43+Debt!I9 -> 241.76806 | J45: =J43+Debt!J9 -> 194.92397 | K45: =K43+Debt!K9 -> 126.80709
B46: DSCR ((EBITDA - capex - tax) / debt service) | G46: =(G39+CF!G12-IS!G19)/G45 -> 1.3019778 | H46: =(H39+CF!H12-IS!H19)/H45 -> 1.6210859 | I46: =(I39+CF!I12-IS!I19)/I45 -> 1.8250947 | J46: =(J39+CF!J12-IS!J19)/J45 -> 2.6460744 | K46: =(K39+CF!K12-IS!K19)/K45 -> 4.393205
...

Sheet WACC
B2: Cost of capital (INR)
B3: CAPM with peer betas unlevered and relevered (Hamada).
B5: Peer | D5: Levered beta | E5: Debt / equity | F5: Tax rate | G5: Unlevered beta
B6: Peer A (pan-India packaged foods) | D6: 0.82 | E6: 0.05 | F6: 0.2517 | G6: =D6/(1+(1-F6)*E6) -> 0.7904262
B7: Peer B (spices and masalas) | D7: 0.91 | E7: 0.12 | F7: 0.2517 | G7: =D7/(1+(1-F7)*E7) -> 0.83501866
B8: Peer C (regional snacks) | D8: 1.05 | E8: 0.25 | F8: 0.2517 | G8: =D8/(1+(1-F8)*E8) -> 0.88452709
B9: Peer D (edible oils and staples) | D9: 0.98 | E9: 0.3 | F9: 0.2517 | G9: =D9/(1+(1-F9)*E9) -> 0.8003332
B10: Peer E (ready-to-cook) | D10: 0.88 | E10: 0 | F10: 0.2517 | G10: =D10/(1+(1-F10)*E10) -> 0.88
B11: Peer F (dairy and beverages) | D11: 0.76 | E11: 0.08 | F11: 0.2517 | G11: =D11/(1+(1-F11)*E11) -> 0.71707313
B13: Median unlevered beta | D13: =MEDIAN(G6:G11) -> 0.81767593
B14: Target debt / capital | D14: 0.1
B15: Target debt / equity | D15: =Target_DC/(1-Target_DC) -> 0.11111111
B16: Relevered beta | D16: =$D$13*(1+(1-Tax_Rate)*$D$15) -> 0.88566114
B17: Risk-free rate (10-year G-sec) | D17: 0.066
B18: Equity risk premium (India) | D18: 0.07
B19: Size / company-specific premium | D19: 0.01
B20: Cost of equity | D20: =Risk_Free+$D$16*Equity_Risk_Premium+Size_Premium -> 0.13799628
B21: Pre-tax cost of debt | D21: 0.09
B22: After-tax cost of debt | D22: =Kd_Pre_Tax*(1-Tax_Rate) -> 0.067347
B23: WACC | D23: =(1-Target_DC)*$D$20+Target_DC*$D$22 -> 0.13093135

Sheet DCF
B2: Discounted cash flow (unlevered, standalone)
B3: FCFF follows the live operating case; the deal's capital structure does not affect it.
B5: Assumptions
B6: Terminal growth (nominal INR) | D6: 0.055
B7: Terminal EV / EBITDA (cross-check) | D7: 13
B8: Mid-year convention (1 = on) | D8: 1
B10: Free cash flow to the firm | C10: INR crore | G10: FY27E | H10: FY28E | I10: FY29E | J10: FY30E | K10: FY31E
B11: EBIT | G11: =IS!G15 -> 406.8 | H11: =IS!H15 -> 481.13592 | I11: =IS!I15 -> 568.85895 | J11: =IS!J15 -> 664.15144 | K11: =IS!K15 -> 753.44506
B12: NOPAT (EBIT x (1 - tax)) | G12: =G11*(1-Tax_Rate) -> 304.40844 | H12: =H11*(1-Tax_Rate) -> 360.03401 | I12: =I11*(1-Tax_Rate) -> 425.67715 | J12: =J11*(1-Tax_Rate) -> 496.98452 | K12: =K11*(1-Tax_Rate) -> 563.80294
B13: Plus: D&A | G13: =IS!G14 -> 67.8 | H13: =IS!H14 -> 76.614 | I13: =IS!I14 -> 86.19075 | J13: =IS!J14 -> 96.53364 | K13: =IS!K14 -> 107.63501
B14: Less: capex | G14: =CF!G12 -> -108.48 | H14: =CF!H12 -> -116.45328 | I14: =CF!I12 -> -120.66705 | J14: =CF!J12 -> -135.1471 | K14: =CF!K12 -> -150.68901
B15: Less: increase in working capital | G15: =CF!G10 -> -28.265753 | H15: =CF!H10 -> -31.544647 | I15: =CF!I10 -> -34.240161 | J15: =CF!J10 -> -36.941592 | K15: =CF!K10 -> -39.904098
B16: Unlevered free cash flow | G16: =G12+G13+G14+G15 -> 235.46269 | H16: =H12+H13+H14+H15 -> 288.65008 | I16: =I12+I13+I14+I15 -> 356.96069 | J16: =J12+J13+J14+J15 -> 421.42948 | K16: =K12+K13+K14+K15 -> 480.84484
B17: Year | G17: 1 | H17: 2 | I17: 3 | J17: 4 | K17: 5
B18: Discount period | G18: =G17-0.5*Mid_Year -> 0.5 | H18: =H17-0.5*Mid_Year -> 1.5 | I18: =I17-0.5*Mid_Year -> 2.5 | J18: =J17-0.5*Mid_Year -> 3.5 | K18: =K17-0.5*Mid_Year -> 4.5
B19: Discount factor | G19: =1/(1+WACC_Rate)^G18 -> 0.94033343 | H19: =1/(1+WACC_Rate)^H18 -> 0.83146818 | I19: =1/(1+WACC_Rate)^I18 -> 0.73520659 | J19: =1/(1+WACC_Rate)^J18 -> 0.65008949 | K19: =1/(1+WACC_Rate)^K18 -> 0.57482666
B20: Present value | G20: =G16*G19 -> 221.41344 | H20: =H16*H19 -> 240.00336 | I20: =I16*I19 -> 262.43985 | J20: =J16*J19 -> 273.96688 | K20: =K16*K19 -> 276.40243
B22: Valuation
B23: Sum of PV of FCFF | D23: =SUM($G$20:$K$20) -> 1274.226
B24: Terminal value: Gordon growth | D24: =$K$16*(1+Terminal_Growth)/(WACC_Rate-Terminal_Growth) -> 6680.9202
B25: PV of terminal value (Gordon) | D25: =$D$24/(1+WACC_Rate)^(5.0-0.5*Mid_Year) -> 3840.371
B26: Terminal value: exit multiple | D26: =DCF_Exit_Multiple*IS!$K$12 -> 11194.041
B27: PV of terminal value (exit multiple) | D27: =$D$26/(1+WACC_Rate)^5.0 -> 6050.7007
B28: Net debt (standalone, pre-deal) | D28: =BS!$D$22-BS!$D$7 -> -60
B29: Enterprise value (Gordon growth) | D29: =$D$23+$D$25 -> 5114.597
B30: Equity value (Gordon growth) | D30: =$D$29-$D$28 -> 5174.597
B31: Value per share (Gordon growth) | D31: =$D$30/Diluted_Shares -> 431.21642
B32: Terminal value share of EV (Gordon growth) | D32: =$D$25/$D$29 -> 0.75086484
B33: Enterprise value (exit multiple) | D33: =$D$23+$D$27 -> 7324.9266
B34: Equity value (exit multiple) | D34: =$D$33-$D$28 -> 7384.9266
B35: Value per share (exit multiple) | D35: =$D$34/Diluted_Shares -> 615.41055
B36: Terminal value share of EV (exit multiple) | D36: =$D$27/$D$33 -> 0.8260425
B38: Cross-checks
B39: Exit multiple implied by the Gordon value | D39: =$D$24*(1+WACC_Rate)^(0.5*Mid_Year)/IS!$K$12 -> 8.2510814
B40: Perpetual growth implied by the exit multiple | D40: =($D$26/(1+WACC_Rate)^(0.5*Mid_Year)*WACC_Rate-$K$16)/($D$26/(1+WACC_Rate)^(0.5*Mid_Year)+$K$16) -> 0.081526092
B41: Gordon value vs unaffected price | D41: =$D$31/Unaffected_Price-1 -> 0.13478004
B42: Gordon value vs offer price | D42: =$D$31/Deal!$D$6-1 -> -0.092175964

Sheet Comps
B2: Trading comparables and precedent transactions
B3: Trading multiples on NTM (FY27E) estimates; precedents on LTM (FY26A) EBITDA.
B5: Trading comparables | D5: Market cap | E5: Net debt | F5: EV | G5: Revenue | H5: EBITDA | I5: Net income | J5: EV / Revenue | K5: EV / EBITDA | L5: P / E | M5: Revenue growth | N5: EBITDA margin
B6: Peer A (pan-India packaged foods) | D6: 35160 | E6: -900 | F6: =D6+E6 -> 34260 | G6: 13800 | H6: 2210 | I6: 1480 | J6: =F6/G6 -> 2.4826087 | K6: =F6/H6 -> 15.502262 | L6: =D6/I6 -> 23.756757 | M6: 0.11 | N6: 0.16
B7: Peer B (spices and masalas) | D7: 8410 | E7: 150 | F7: =D7+E7 -> 8560 | G7: 3900 | H7: 620 | I7: 390 | J7: =F7/G7 -> 2.1948718 | K7: =F7/H7 -> 13.806452 | L7: =D7/I7 -> 21.564103 | M7: 0.13 | N7: 0.159
B8: Peer C (regional snacks) | D8: 4400 | E8: 420 | F8: =D8+E8 -> 4820 | G8: 3300 | H8: 430 | I8: 240 | J8: =F8/G8 -> 1.4606061 | K8: =F8/H8 -> 11.209302 | L8: =D8/I8 -> 18.333333 | M8: 0.15 | N8: 0.13
B9: Peer D (edible oils and staples) | D9: 12910 | E9: 2600 | F9: =D9+E9 -> 15510 | G9: 26500 | H9: 1650 | I9: 820 | J9: =F9/G9 -> 0.58528302 | K9: =F9/H9 -> 9.4 | L9: =D9/I9 -> 15.743902 | M9: 0.07 | N9: 0.062
B10: Peer E (ready-to-cook) | D10: 3550 | E10: -120 | F10: =D10+E10 -> 3430 | G10: 1650 | H10: 235 | I10: 160 | J10: =F10/G10 -> 2.0787879 | K10: =F10/H10 -> 14.595745 | L10: =D10/I10 -> 22.1875 | M10: 0.18 | N10: 0.142
B11: Peer F (dairy and beverages) | D11: 8820 | E11: 380 | F11: =D11+E11 -> 9200 | G11: 8200 | H11: 760 | I11: 455 | J11: =F11/G11 -> 1.1219512 | K11: =F11/H11 -> 12.105263 | L11: =D11/I11 -> 19.384615 | M11: 0.12 | N11: 0.093
B12: Peer G (bakery and biscuits) | D12: 5020 | E12: 60 | F12: =D12+E12 -> 5080 | G12: 4100 | H12: 470 | I12: 300 | J12: =F12/G12 -> 1.2390244 | K12: =F12/H12 -> 10.808511 | L12: =D12/I12 -> 16.733333 | M12: 0.1 | N12: 0.115
B13: Peer H (premium foods) | D13: 4370 | E13: -60 | F13: =D13+E13 -> 4310 | G13: 1500 | H13: 255 | I13: 175 | J13: =F13/G13 -> 2.8733333 | K13: =F13/H13 -> 16.901961 | L13: =D13/I13 -> 24.971429 | M13: 0.2 | N13: 0.17
B14: Maximum | J14: =MAX(J6:J13) -> 2.8733333 | K14: =MAX(K6:K13) -> 16.901961 | L14: =MAX(L6:L13) -> 24.971429 | M14: =MAX(M6:M13) -> 0.2 | N14: =MAX(N6:N13) -> 0.17
B15: 75th percentile | J15: =QUARTILE(J6:J13,3) -> 2.266806 | K15: =QUARTILE(K6:K13,3) -> 14.822374 | L15: =QUARTILE(L6:L13,3) -> 22.579814 | M15: =QUARTILE(M6:M13,3) -> 0.1575 | N15: =QUARTILE(N6:N13,3) -> 0.15925
B16: Median | J16: =MEDIAN(J6:J13) -> 1.769697 | K16: =MEDIAN(K6:K13) -> 12.955857 | L16: =MEDIAN(L6:L13) -> 20.474359 | M16: =MEDIAN(M6:M13) -> 0.125 | N16: =MEDIAN(N6:N13) -> 0.136
B17: Mean | J17: =AVERAGE(J6:J13) -> 1.7545583 | K17: =AVERAGE(K6:K13) -> 13.041187 | L17: =AVERAGE(L6:L13) -> 20.334372 | M17: =AVERAGE(M6:M13) -> 0.1325 | N17: =AVERAGE(N6:N13) -> 0.128875
B18: 25th percentile | J18: =QUARTILE(J6:J13,1) -> 1.2097561 | K18: =QUARTILE(K6:K13,1) -> 11.109104 | L18: =QUARTILE(L6:L13,1) -> 17.933333 | M18: =QUARTILE(M6:M13,1) -> 0.1075 | N18: =QUARTILE(N6:N13,1) -> 0.1095
B19: Minimum | J19: =MIN(J6:J13) -> 0.58528302 | K19: =MIN(K6:K13) -> 9.4 | L19: =MIN(L6:L13) -> 15.743902 | M19: =MIN(M6:M13) -> 0.07 | N19: =MIN(N6:N13) -> 0.062
B22: Implied value of the target
B23: Target revenue, NTM (FY27E) | D23: =IS!$G$6 -> 2712
B24: Target EBITDA, NTM (FY27E) | D24: =IS!$G$12 -> 474.6
B25: Target standalone net income, NTM (FY27E) (pre-deal capital structure) | D25: =(IS!$G$15-IS!$F$17+IS!$F$16)*(1-Tax_Rate) -> 302.16354
B26: Standalone net debt | D26: =BS!$D$22-BS!$D$7 -> -60
B28: Implied price per share | D28: 25th pct | E28: Median | F28: 75th pct
B29: EV / Revenue | D29: =($J$18*$D$23-$D$26)/Diluted_Shares -> 278.40488 | E29: =($J$16*$D$23-$D$26)/Diluted_Shares -> 404.95152 | F29: =($J$15*$D$23-$D$26)/Diluted_Shares -> 517.29816
B30: EV / EBITDA | D30: =($K$18*$D$24-$D$26)/Diluted_Shares -> 444.36508 | E30: =($K$16*$D$24-$D$26)/Diluted_Shares -> 517.40416 | F30: =($K$15*$D$24-$D$26)/Diluted_Shares -> 591.2249
B31: P / E | D31: =($L$18*$D$25)/Diluted_Shares -> 451.56662 | E31: =($L$16*$D$25)/Diluted_Shares -> 515.5504 | F31: =($L$15*$D$25)/Diluted_Shares -> 568.56638
B33: Precedent transactions | C33: Year | D33: EV / LTM EBITDA | E33: Premium | F33: Acquirer
B34: Precedent 1 (regional spices brand) | C34: FY22 | D34: 17.5 | E34: 0.28 | F34: Strategic acquirer
B35: Precedent 2 (ready-to-eat brand) | C35: FY23 | D35: 14.2 | E35: 0.22 | F35: Financial sponsor
B36: Precedent 3 (packaged staples) | C36: FY23 | D36: 12.6 | E36: 0.18 | F36: Financial sponsor
B37: Precedent 4 (snacks platform) | C37: FY24 | D37: 18 | E37: 0.35 | F37: Strategic acquirer
B38: Precedent 5 (dairy brand) | C38: FY25 | D38: 13.1 | E38: 0.2 | F38: Financial sponsor
B39: Precedent 6 (condiments brand) | C39: FY25 | D39: 15.4 | E39: 0.26 | F39: Strategic acquirer
B40: 75th percentile | D40: =QUARTILE(D34:D39,3) -> 16.975 | E40: =QUARTILE(E34:E39,3) -> 0.275
B41: Median | D41: =MEDIAN(D34:D39) -> 14.8 | E41: =MEDIAN(E34:E39) -> 0.24
B42: 25th percentile | D42: =QUARTILE(D34:D39,1) -> 13.375 | E42: =QUARTILE(E34:E39,1) -> 0.205
B44: Implied price per share | D44: 25th pct | E44: Median | F44: 75th pct
B45: EV / LTM EBITDA (FY26A) | D45: =($D$42*Deal!$D$11-$D$26)/Diluted_Shares -> 459.75 | E45: =($D$41*Deal!$D$11-$D$26)/Diluted_Shares -> 508.2 | F45: =($D$40*Deal!$D$11-$D$26)/Diluted_Shares -> 582.15
B46: Premium to unaffected price | D46: =Unaffected_Price*(1+$E$42) -> 457.9 | E46: =Unaffected_Price*(1+$E$41) -> 471.2 | F46: =Unaffected_Price*(1+$E$40) -> 484.5

Sheet Sensitivity
B2: Sensitivity tables
B3: Static values computed by the STOCKEX engine (base case). Re-run `deal-model` after changing inputs.
B6: Sponsor IRR: entry vs exit multiple
B7: Entry EV / LTM EBITDA (rows) / Exit EV / EBITDA (columns)
D8: 11.5 | E8: 12.5 | F8: 13.5 | G8: 14.5 | H8: 15.5
C9: 11.823529 | D9: 0.21440662 | E9: 0.23503867 | F9: 0.2543776 | G9: 0.2725926 | H9: 0.28982076
C10: 12.823529 | D10: 0.1876073 | E10: 0.20771672 | F10: 0.22656966 | G10: 0.24433005 | H10: 0.26113078
C11: 13.823529 | D11: 0.16415879 | E11: 0.18380561 | F11: 0.20222862 | G11: 0.21958704 | H11: 0.23601001
C12: 14.823529 | D12: 0.14337573 | E12: 0.16260785 | F12: 0.18064566 | G12: 0.1976441 | H12: 0.21372891
C13: 15.823529 | D13: 0.12475917 | E13: 0.14361565 | F13: 0.16130472 | G13: 0.1779774 | H13: 0.19375634
B16: Sponsor MOIC: entry vs exit multiple
B17: Entry EV / LTM EBITDA (rows) / Exit EV / EBITDA (columns)
D18: 11.5 | E18: 12.5 | F18: 13.5 | G18: 14.5 | H18: 15.5
C19: 11.823529 | D19: 2.6413177 | E19: 2.8734443 | F19: 3.1055709 | G19: 3.3376975 | H19: 3.5698241
C20: 12.823529 | D20: 2.3624591 | E20: 2.5693626 | F20: 2.7762661 | G20: 2.9831696 | H20: 3.1900731
C21: 13.823529 | D21: 2.1382629 | E21: 2.3248876 | F21: 2.5115123 | G21: 2.698137 | H21: 2.8847617
C22: 14.823529 | D22: 1.9540913 | E22: 2.1240574 | F22: 2.2940236 | G22: 2.4639897 | H22: 2.6339558
C23: 15.823529 | D23: 1.8001045 | E23: 1.9561423 | F23: 2.1121802 | G23: 2.268218 | H23: 2.4242558
B26: Sponsor IRR: leverage vs exit multiple
B27: Total debt / LTM EBITDA (rows) / Exit EV / EBITDA (columns)
D28: 11.5 | E28: 12.5 | F28: 13.5 | G28: 14.5 | H28: 15.5
C29: 3 | D29: 0.15805573 | E29: 0.17642272 | F29: 0.19370952 | G29: 0.21004935 | H29: 0.22555148
C30: 3.5 | D30: 0.16101866 | E30: 0.18000161 | F30: 0.19783622 | G30: 0.21466788 | H30: 0.23061521
C31: 4 | D31: 0.16415879 | E31: 0.18380561 | F31: 0.20222862 | G31: 0.21958704 | H31: 0.23601001
C32: 4.5 | D32: 0.16728432 | E32: 0.18766319 | F32: 0.20673234 | G32: 0.22466718 | H32: 0.24160908
C33: 5 | D33: 0.16994165 | E33: 0.1911625 | F33: 0.21097075 | G33: 0.22956184 | H33: 0.24709211
B36: Sponsor IRR: growth vs margin shift
B37: Revenue growth shift (every year) (rows) / EBITDA margin shift (every year) (columns)
D38: -0.02 | E38: -0.01 | F38: 0 | G38: 0.01 | H38: 0.02
C39: -0.04 | D39: 0.12249131 | E39: 0.13933145 | F39: 0.15518464 | G39: 0.16991972 | H39: 0.18385058
C40: -0.02 | D40: 0.14648249 | E40: 0.16325807 | F40: 0.17885775 | G40: 0.19356202 | H40: 0.20753112
C41: 0 | D41: 0.17011039 | E41: 0.18669076 | F41: 0.20222862 | G41: 0.21698199 | H41: 0.23102009
C42: 0.02 | D42: 0.19332734 | E42: 0.20979006 | F42: 0.22539348 | G42: 0.24021541 | H42: 0.25433763
C43: 0.04 | D43: 0.21615581 | E43: 0.23269525 | F43: 0.24838481 | G43: 0.2632872 | H43: 0.27750777
B46: DCF value per share: WACC vs terminal growth
B47: WACC (rows) / Terminal growth (columns)
D48: 0.045 | E48: 0.05 | F48: 0.055 | G48: 0.06 | H48: 0.065
C49: 0.12093135 | D49: 443.61049 | E49: 468.55689 | F49: 497.28698 | G49: 530.73222 | H49: 570.15716
C50: 0.12593135 | D50: 415.82691 | E50: 437.35295 | F50: 461.91376 | G50: 490.19978 | H50: 523.12807
C51: 0.13093135 | D51: 391.29333 | E51: 410.02164 | F51: 431.21642 | G51: 455.39927 | H51: 483.25
...

Sheet Football
B2: Valuation football field (per share)
B3: Static values from the STOCKEX engine.
B5: Method | D5: Low | E5: High | F5: Mid
B6: 52-week trading range | D6: 331 | E6: 436 | F6: 383.5
B7: Trading comps EV/EBITDA, NTM (FY27E) (Q1-Q3) | D7: 444.36508 | E7: 591.2249 | F7: 517.79499
B8: Trading comps P/E, NTM (FY27E) (Q1-Q3) | D8: 451.56662 | E8: 568.56638 | F8: 510.0665
B9: Precedents EV/EBITDA, LTM (FY26A) (Q1-Q3) | D9: 459.75 | E9: 582.15 | F9: 520.95
B10: Precedent premiums to unaffected (Q1-Q3) | D10: 457.9 | E10: 484.5 | F10: 471.2
B11: DCF, WACC +/-0.5%, g +/-0.5% | D11: 385.8866 | E11: 490.19978 | F11: 438.04319
B12: LBO ability to pay (25%-20% sponsor IRR) | D12: 412.04188 | E12: 478.33375 | F12: 445.18781
B14: Unaffected price | D14: 380
B15: Offer price | D15: 475
B16: Maximum bid (lower of base-case hurdle IRR and downside 1.0x) | D16: 478.33375

Sheet Checks
B2: Model integrity checks
B3: Every check must be zero. The overall flag feeds the cover.
B5: Per-year checks | C5: INR crore | G5: FY27E | H5: FY28E | I5: FY29E | J5: FY30E | K5: FY31E
B6: Balance sheet balances (assets - claims) | G6: =BS!G28 -> 0 | H6: =BS!H28 -> 0 | I6: =BS!I28 -> 0 | J6: =BS!J28 -> 0 | K6: =BS!K28 -> 0
B7: Cash ties to the sweep (BS cash - (min cash + cash after revolver - prepayments)) | G7: =BS!G7-(Min_Cash+Debt!G13-Debt!G44) -> -1.4210855e-14 | H7: =BS!H7-(Min_Cash+Debt!H13-Debt!H44) -> -1.4210855e-14 | I7: =BS!I7-(Min_Cash+Debt!I13-Debt!I44) -> -1.4210855e-14 | J7: =BS!J7-(Min_Cash+Debt!J13-Debt!J44) -> 0 | K7: =BS!K7-(Min_Cash+Debt!K13-Debt!K44) -> 1.1368684e-13
B8: Revolver above commitment | G8: =MAX(0,Debt!G19-Rev_Commitment) -> 0 | H8: =MAX(0,Debt!H19-Rev_Commitment) -> 0 | I8: =MAX(0,Debt!I19-Rev_Commitment) -> 0 | J8: =MAX(0,Debt!J19-Rev_Commitment) -> 0 | K8: =MAX(0,Debt!K19-Rev_Commitment) -> 0
B9: Liquidity shortfall flag (cash below minimum after the revolver) | G9: =IF(Debt!G13<0,1,0) -> 0 | H9: =IF(Debt!H13<0,1,0) -> 0 | I9: =IF(Debt!I13<0,1,0) -> 0 | J9: =IF(Debt!J13<0,1,0) -> 0 | K9: =IF(Debt!K13<0,1,0) -> 0
B11: Transaction checks
B12: Sources - uses | D12: =Deal!$D$38 -> 0
B13: Pro forma balance sheet balances | D13: =BS!$F$28 -> 0
B14: Value-creation bridge reconciles | D14: =Returns!$D$28 -> 2.7284841e-12
B15: Overall | D15: =IF(AND(MAX($G$6:$K$6)<0.001,MAX($G$7:$K$7)<0.001,MAX($G$8:$K$8)<0.001,MIN($G$6:$K$6)>-0.001,MIN($G$7:$K$7)>-0.001,ABS($D$12)<0.001,ABS($D$13)<0.001,ABS($D$14)<0.001),"ALL CHECKS PASS","CHECK FAILURE") -> ALL CHECKS PASS
